Workbook
Name Slicer_Department1: #N/A
Name TotalHeadcount_KPI: GETPIVOTDATA("Employee ID",'PIVOT TABLES'!$B$4)

Sheet DASHBOARD
B37: Employee ID | C37: Full Name | D37: Department | E37: Gender | F37: Age | G37: Join Date | H37: Exit Date | I37: Exit Reason | J37: Status
B38: {=IFERROR(INDEX(EmployeeData[Employee ID], ROW() - 37), "")} -> 1001 | C38: {=IFERROR(INDEX(EmployeeData[Full Name], ROW() - 37), "")} -> Paz Cruz Dela Cruz | D38: {=IFERROR(INDEX(EmployeeData[Department], ROW() - 37), "")} -> Marketing | E38: {=IFERROR(INDEX(EmployeeData[Gender], ROW() - 37), "")} -> Female | F38: {=IFERROR(INDEX(EmployeeData[Age], ROW() - 37), "")} -> 38 | G38: {=IFERROR(INDEX(EmployeeData[Join Date], ROW() - 37), "")} -> 44104 | H38: {=IFERROR(IF(INDEX(EmployeeData[Exit Date], ROW() - 37)=0, "",INDEX(EmployeeData[Exit Date], ROW() - 37)),"")} -> 45702 | I38: {=IFERROR(IF(INDEX(EmployeeData[Exit Reason], ROW() - 37)=0, "",INDEX(EmployeeData[Exit Reason], ROW() - 37)),"")} -> Better Opportunity | J38: {=IFERROR(INDEX(EmployeeData[Status], ROW() - 37), "")} -> Exited
B39: {=IFERROR(INDEX(EmployeeData[Employee ID], ROW() - 37), "")} -> 1002 | C39: {=IFERROR(INDEX(EmployeeData[Full Name], ROW() - 37), "")} -> Paz Aguilar Camacho | D39: {=IFERROR(INDEX(EmployeeData[Department], ROW() - 37), "")} -> Customer Support | E39: {=IFERROR(INDEX(EmployeeData[Gender], ROW() - 37), "")} -> Female | F39: {=IFERROR(INDEX(EmployeeData[Age], ROW() - 37), "")} -> 53 | G39: {=IFERROR(INDEX(EmployeeData[Join Date], ROW() - 37), "")} -> 45566 | H39: {=IFERROR(IF(INDEX(EmployeeData[Exit Date], ROW() - 37)=0, "",INDEX(EmployeeData[Exit Date], ROW() - 37)),"")} -> 45859 | I39: {=IFERROR(IF(INDEX(EmployeeData[Exit Reason], ROW() - 37)=0, "",INDEX(EmployeeData[Exit Reason], ROW() - 37)),"")} -> Personal Reasons | J39: {=IFERROR(INDEX(EmployeeData[Status], ROW() - 37), "")} -> Exited
B40: {=IFERROR(INDEX(EmployeeData[Employee ID], ROW() - 37), "")} -> 1003 | C40: {=IFERROR(INDEX(EmployeeData[Full Name], ROW() - 37), "")} -> Celine Diaz Domingo | D40: {=IFERROR(INDEX(EmployeeData[Department], ROW() - 37), "")} -> Sales | E40: {=IFERROR(INDEX(EmployeeData[Gender], ROW() - 37), "")} -> Female | F40: {=IFERROR(INDEX(EmployeeData[Age], ROW() - 37), "")} -> 31 | G40: {=IFERROR(INDEX(EmployeeData[Join Date], ROW() - 37), "")} -> 45960 | H40: {=IFERROR(IF(INDEX(EmployeeData[Exit Date], ROW() - 37)=0, "",INDEX(EmployeeData[Exit Date], ROW() - 37)),"")} | I40: {=IFERROR(IF(INDEX(EmployeeData[Exit Reason], ROW() - 37)=0, "",INDEX(EmployeeData[Exit Reason], ROW() - 37)),"")} | J40: {=IFERROR(INDEX(EmployeeData[Status], ROW() - 37), "")} -> Active
B41: {=IFERROR(INDEX(EmployeeData[Employee ID], ROW() - 37), "")} -> 1004 | C41: {=IFERROR(INDEX(EmployeeData[Full Name], ROW() - 37), "")} -> Eduardo Torres Dela Torre | D41: {=IFERROR(INDEX(EmployeeData[Department], ROW() - 37), "")} -> Customer Support | E41: {=IFERROR(INDEX(EmployeeData[Gender], ROW() - 37), "")} -> Male | F41: {=IFERROR(INDEX(EmployeeData[Age], ROW() - 37), "")} -> 43 | G41: {=IFERROR(INDEX(EmployeeData[Join Date], ROW() - 37), "")} -> 44509 | H41: {=IFERROR(IF(INDEX(EmployeeData[Exit Date], ROW() - 37)=0, "",INDEX(EmployeeData[Exit Date], ROW() - 37)),"")} | I41: {=IFERROR(IF(INDEX(EmployeeData[Exit Reason], ROW() - 37)=0, "",INDEX(EmployeeData[Exit Reason], ROW() - 37)),"")} | J41: {=IFERROR(INDEX(EmployeeData[Status], ROW() - 37), "")} -> Active
B42: {=IFERROR(INDEX(EmployeeData[Employee ID], ROW() - 37), "")} -> 1005 | C42: {=IFERROR(INDEX(EmployeeData[Full Name], ROW() - 37), "")} -> Jerome Ocampo Macapagal | D42: {=IFERROR(INDEX(EmployeeData[Department], ROW() - 37), "")} -> Finance | E42: {=IFERROR(INDEX(EmployeeData[Gender], ROW() - 37), "")} -> Male | F42: {=IFERROR(INDEX(EmployeeData[Age], ROW() - 37), "")} -> 56 | G42: {=IFERROR(INDEX(EmployeeData[Join Date], ROW() - 37), "")} -> 44301 | H42: {=IFERROR(IF(INDEX(EmployeeData[Exit Date], ROW() - 37)=0, "",INDEX(EmployeeData[Exit Date], ROW() - 37)),"")} | I42: {=IFERROR(IF(INDEX(EmployeeData[Exit Reason], ROW() - 37)=0, "",INDEX(EmployeeData[Exit Reason], ROW() - 37)),"")} | J42: {=IFERROR(INDEX(EmployeeData[Status], ROW() - 37), "")} -> Active
B43: {=IFERROR(INDEX(EmployeeData[Employee ID], ROW() - 37), "")} -> 1006 | C43: {=IFERROR(INDEX(EmployeeData[Full Name], ROW() - 37), "")} -> Lourdes Santiago Panganiban | D43: {=IFERROR(INDEX(EmployeeData[Department], ROW() - 37), "")} -> Customer Support | E43: {=IFERROR(INDEX(EmployeeData[Gender], ROW() - 37), "")} -> Female | F43: {=IFERROR(INDEX(EmployeeData[Age], ROW() - 37), "")} -> 39 | G43: {=IFERROR(INDEX(EmployeeData[Join Date], ROW() - 37), "")} -> 43427 | H43: {=IFERROR(IF(INDEX(EmployeeData[Exit Date], ROW() - 37)=0, "",INDEX(EmployeeData[Exit Date], ROW() - 37)),"")} | I43: {=IFERROR(IF(INDEX(EmployeeData[Exit Reason], ROW() - 37)=0, "",INDEX(EmployeeData[Exit Reason], ROW() - 37)),"")} | J43: {=IFERROR(INDEX(EmployeeData[Status], ROW() - 37), "")} -> Active
B44: {=IFERROR(INDEX(EmployeeData[Employee ID], ROW() - 37), "")} -> 1007 | C44: {=IFERROR(INDEX(EmployeeData[Full Name], ROW() - 37), "")} -> Manuel Quiambao | D44: {=IFERROR(INDEX(EmployeeData[Department], ROW() - 37), "")} -> Customer Support | E44: {=IFERROR(INDEX(EmployeeData[Gender], ROW() - 37), "")} -> Male | F44: {=IFERROR(INDEX(EmployeeData[Age], ROW() - 37), "")} -> 38 | G44: {=IFERROR(INDEX(EmployeeData[Join Date], ROW() - 37), "")} -> 45975 | H44: {=IFERROR(IF(INDEX(EmployeeData[Exit Date], ROW() - 37)=0, "",INDEX(EmployeeData[Exit Date], ROW() - 37)),"")} | I44: {=IFERROR(IF(INDEX(EmployeeData[Exit Reason], ROW() - 37)=0, "",INDEX(EmployeeData[Exit Reason], ROW() - 37)),"")} | J44: {=IFERROR(INDEX(EmployeeData[Status], ROW() - 37), "")} -> Active
B45: {=IFERROR(INDEX(EmployeeData[Employee ID], ROW() - 37), "")} -> 1008 | C45: {=IFERROR(INDEX(EmployeeData[Full Name], ROW() - 37), "")} -> Pacita Bautista Guevarra | D45: {=IFERROR(INDEX(EmployeeData[Department], ROW() - 37), "")} -> Marketing | E45: {=IFERROR(INDEX(EmployeeData[Gender], ROW() - 37), "")} -> Female | F45: {=IFERROR(INDEX(EmployeeData[Age], ROW() - 37), "")} -> 50 | G45: {=IFERROR(INDEX(EmployeeData[Join Date], ROW() - 37), "")} -> 44655 | H45: {=IFERROR(IF(INDEX(EmployeeData[Exit Date], ROW() - 37)=0, "",INDEX(EmployeeData[Exit Date], ROW() - 37)),"")} -> 46055 | I45: {=IFERROR(IF(INDEX(EmployeeData[Exit Reason], ROW() - 37)=0, "",INDEX(EmployeeData[Exit Reason], ROW() - 37)),"")} -> Personal Reasons | J45: {=IFERROR(INDEX(EmployeeData[Status], ROW() - 37), "")} -> Exited
B46: {=IFERROR(INDEX(EmployeeData[Employee ID], ROW() - 37), "")} -> 1009 | C46: {=IFERROR(INDEX(EmployeeData[Full Name], ROW() - 37), "")} -> Tess Ang Miranda | D46: {=IFERROR(INDEX(EmployeeData[Department], ROW() - 37), "")} -> Customer Support | E46: {=IFERROR(INDEX(EmployeeData[Gender], ROW() - 37), "")} -> Female | F46: {=IFERROR(INDEX(EmployeeData[Age], ROW() - 37), "")} -> 41 | G46: {=IFERROR(INDEX(EmployeeData[Join Date], ROW() - 37), "")} -> 44744 | H46: {=IFERROR(IF(INDEX(EmployeeData[Exit Date], ROW() - 37)=0, "",INDEX(EmployeeData[Exit Date], ROW() - 37)),"")} -> 45266 | I46: {=IFERROR(IF(INDEX(EmployeeData[Exit Reason], ROW() - 37)=0, "",INDEX(EmployeeData[Exit Reason], ROW() - 37)),"")} -> Resignation | J46: {=IFERROR(INDEX(EmployeeData[Status], ROW() - 37), "")} -> Exited
B47: {=IFERROR(INDEX(EmployeeData[Employee ID], ROW() - 37), "")} -> 1010 | C47: {=IFERROR(INDEX(EmployeeData[Full Name], ROW() - 37), "")} -> Gloria Chan | D47: {=IFERROR(INDEX(EmployeeData[Department], ROW() - 37), "")} -> IT | E47: {=IFERROR(INDEX(EmployeeData[Gender], ROW() - 37), "")} -> Other | F47: {=IFERROR(INDEX(EmployeeData[Age], ROW() - 37), "")} -> 50 | G47: {=IFERROR(INDEX(EmployeeData[Join Date], ROW() - 37), "")} -> 43686 | H47: {=IFERROR(IF(INDEX(EmployeeData[Exit Date], ROW() - 37)=0, "",INDEX(EmployeeData[Exit Date], ROW() - 37)),"")} -> 44786 | I47: {=IFERROR(IF(INDEX(EmployeeData[Exit Reason], ROW() - 37)=0, "",INDEX(EmployeeData[Exit Reason], ROW() - 37)),"")} -> Personal Reasons | J47: {=IFERROR(INDEX(EmployeeData[Status], ROW() - 37), "")} -> Exited
B48: {=IFERROR(INDEX(EmployeeData[Employee ID], ROW() - 37), "")} -> 1011 | C48: {=IFERROR(INDEX(EmployeeData[Full Name], ROW() - 37), "")} -> Crisanto Bautista Cueto | D48: {=IFERROR(INDEX(EmployeeData[Department], ROW() - 37), "")} -> IT | E48: {=IFERROR(INDEX(EmployeeData[Gender], ROW() - 37), "")} -> Male | F48: {=IFERROR(INDEX(EmployeeData[Age], ROW() - 37), "")} -> 44 | G48: {=IFERROR(INDEX(EmployeeData[Join Date], ROW() - 37), "")} -> 43999 | H48: {=IFERROR(IF(INDEX(EmployeeData[Exit Date], ROW() - 37)=0, "",INDEX(EmployeeData[Exit Date], ROW() - 37)),"")} | I48: {=IFERROR(IF(INDEX(EmployeeData[Exit Reason], ROW() - 37)=0, "",INDEX(EmployeeData[Exit Reason], ROW() - 37)),"")} | J48: {=IFERROR(INDEX(EmployeeData[Status], ROW() - 37), "")} -> Active
B49: {=IFERROR(INDEX(EmployeeData[Employee ID], ROW() - 37), "")} -> 1012 | C49: {=IFERROR(INDEX(EmployeeData[Full Name], ROW() - 37), "")} -> Teresa Go Salazar | D49: {=IFERROR(INDEX(EmployeeData[Department], ROW() - 37), "")} -> Sales | E49: {=IFERROR(INDEX(EmployeeData[Gender], ROW() - 37), "")} -> Female | F49: {=IFERROR(INDEX(EmployeeData[Age], ROW() - 37), "")} -> 31 | G49: {=IFERROR(INDEX(EmployeeData[Join Date], ROW() - 37), "")} -> 45888 | H49: {=IFERROR(IF(INDEX(EmployeeData[Exit Date], ROW() - 37)=0, "",INDEX(EmployeeData[Exit Date], ROW() - 37)),"")} | I49: {=IFERROR(IF(INDEX(EmployeeData[Exit Reason], ROW() - 37)=0, "",INDEX(EmployeeData[Exit Reason], ROW() - 37)),"")} | J49: {=IFERROR(INDEX(EmployeeData[Status], ROW() - 37), "")} -> Active
... B5038: {=IFERROR(INDEX(EmployeeData[Employee ID], ROW() - 37), "")} | C5038: {=IFERROR(INDEX(EmployeeData[Full Name], ROW() - 37), "")} | D5038: {=IFERROR(INDEX(EmployeeData[Department], ROW() - 37), "")} | E5038: {=IFERROR(INDEX(EmployeeData[Gender], ROW() - 37), "")} | F5038: {=IFERROR(INDEX(EmployeeData[Age], ROW() - 37), "")} | G5038: {=IFERROR(INDEX(EmployeeData[Join Date], ROW() - 37), "")} | H5038: {=IFERROR(IF(INDEX(EmployeeData[Exit Date], ROW() - 37)=0, "",INDEX(EmployeeData[Exit Date], ROW() - 37)),"")} | I5038: {=IFERROR(IF(INDEX(EmployeeData[Exit Reason], ROW() - 37)=0, "",INDEX(EmployeeData[Exit Reason], ROW() - 37)),"")} | J5038: {=IFERROR(INDEX(EmployeeData[Status], ROW() - 37), "")}

Sheet PIVOT TABLES
B2: TOTAL HEADCOUNT (2018 - 2025) | K2: EXIT REASON BREAKDOWN | O2: NEW HIRES VS. EXITS OVER TIME | V2: COMPANY TURNOVER RATE OVER TIME | AE2: TENURE BEFORE EXIT | AL2: ACTIVE & EXIT BY AGE BRACKET
B4: Employee Count | K4: Reason | L4: Exit Count | O4: New Hires per Year & Quarter | R4: Exited per Year & Quarter | V4: Quarter | W4: End Date | X4: Start Date | Y4: Cumulative Headcount-as-of-Quarter End | Z4: Exits per Quarter | AA4: Average Headcount | AB4: Turnover Rate % | AE4: Status | AF4: Average Tenure (days) | AL4: Active vs. Exited
B5: 1081 | K5: Better Opportunity | L5: 81 | P5: Active | S5: Exited | V5: Q1 2018 | W5: =DATE(2018,3,31) -> 43190 | X5: =DATE(2018,1,1) -> 43101 | Y5: =COUNTIFS(EmployeeData[Join Date], "<="&W5, EmployeeData[Exit Date], ">"&W5) + COUNTIFS(EmployeeData[Join Date], "<="&W5, EmployeeData[Exit Date], "") -> 28 | Z5: =COUNTIFS(EmployeeData[Exit Date], ">="&X5, EmployeeData[Exit Date], "<="&W5) -> 0 | AB5: 0 | AE5: Active | AF5: 1662.5067 | AL5: Age Bracket | AM5: Active | AN5: Exited
K6: Termination | L6: 68 | O6: 2018 | P6: 82 | R6: 2018 | S6: 3 | V6: Q2 2018 | W6: =DATE(2018,6,30) -> 43281 | X6: =DATE(2018,4,1) -> 43191 | Y6: =COUNTIFS(EmployeeData[Join Date], "<="&W6, EmployeeData[Exit Date], ">"&W6) + COUNTIFS(EmployeeData[Join Date], "<="&W6, EmployeeData[Exit Date], "") -> 58 | Z6: =COUNTIFS(EmployeeData[Exit Date], ">="&X6, EmployeeData[Exit Date], "<="&W6) -> 1 | AA6: =SUM(Y6,Y5)/2 -> 43 | AB6: =Z6/AA6 -> 0.023255814 | AE6: Exited | AF6: 800.89614 | AL6: 20s | AM6: 153 | AN6: 92
K7: Resignation | L7: 64 | O7: Qtr1 | P7: 18 | R7: Qtr1 | V7: Q3 2018 | W7: =DATE(2018,9,30) -> 43373 | X7: =DATE(2018,7,1) -> 43282 | Y7: =COUNTIFS(EmployeeData[Join Date], "<="&W7, EmployeeData[Exit Date], ">"&W7) + COUNTIFS(EmployeeData[Join Date], "<="&W7, EmployeeData[Exit Date], "") -> 98 | Z7: =COUNTIFS(EmployeeData[Exit Date], ">="&X7, EmployeeData[Exit Date], "<="&W7) -> 2 | AA7: =SUM(Y7,Y6)/2 -> 78 | AB7: =Z7/AA7 -> 0.025641026 | AE7: Grand Total | AF7: 1332.5282 | AL7: 30s | AM7: 162 | AN7: 83
B8: TURNOVER RATE (Exited vs. Total Headcount) | K8: Personal Reasons | L8: 46 | O8: Qtr2 | P8: 21 | R8: Qtr2 | S8: 1 | V8: Q4 2018 | W8: =DATE(2018,12,31) -> 43465 | X8: =DATE(2018,10,1) -> 43374 | Y8: =COUNTIFS(EmployeeData[Join Date], "<="&W8, EmployeeData[Exit Date], ">"&W8) + COUNTIFS(EmployeeData[Join Date], "<="&W8, EmployeeData[Exit Date], "") -> 143 | Z8: =COUNTIFS(EmployeeData[Exit Date], ">="&X8, EmployeeData[Exit Date], "<="&W8) -> 0 | AA8: =SUM(Y8,Y7)/2 -> 120.5 | AB8: =Z8/AA8 -> 0 | AL8: 40s | AM8: 198 | AN8: 101
K9: Retirement | L9: 44 | O9: Qtr3 | P9: 19 | R9: Qtr3 | S9: 2 | V9: Q1 2019 | W9: =DATE(2019,3,31) -> 43555 | X9: =DATE(2019,1,1) -> 43466 | Y9: =COUNTIFS(EmployeeData[Join Date], "<="&W9, EmployeeData[Exit Date], ">"&W9) + COUNTIFS(EmployeeData[Join Date], "<="&W9, EmployeeData[Exit Date], "") -> 186 | Z9: =COUNTIFS(EmployeeData[Exit Date], ">="&X9, EmployeeData[Exit Date], "<="&W9) -> 0 | AA9: =SUM(Y9,Y8)/2 -> 164.5 | AB9: =Z9/AA9 -> 0 | AE9: Average Tenure (Active) | AF9: =DATEDIF(0,GETPIVOTDATA("Tenure (days)",$AE$4,"Status","Active"),"Y") & " years " & DATEDIF(0,GETPIVOTDATA("Tenure (days)",$AE$4,"Status","Active"),"YM") & " months" -> 4 years 6 months | AL9: 50s | AM9: 154 | AN9: 119
B10: Status | C10: Employee Count | K10: Health Issues | L10: 39 | O10: Qtr4 | P10: 24 | R10: Qtr4 | V10: Q2 2019 | W10: =DATE(2019,6,30) -> 43646 | X10: =DATE(2019,4,1) -> 43556 | Y10: =COUNTIFS(EmployeeData[Join Date], "<="&W10, EmployeeData[Exit Date], ">"&W10) + COUNTIFS(EmployeeData[Join Date], "<="&W10, EmployeeData[Exit Date], "") -> 213 | Z10: =COUNTIFS(EmployeeData[Exit Date], ">="&X10, EmployeeData[Exit Date], "<="&W10) -> 1 | AA10: =SUM(Y10,Y9)/2 -> 199.5 | AB10: =Z10/AA10 -> 0.0050125313 | AE10: Average Tenure (Exited) | AF10: =DATEDIF(0,GETPIVOTDATA("Tenure (days)",$AE$4,"Status","Exited"),"Y") & " years " & DATEDIF(0,GETPIVOTDATA("Tenure (days)",$AE$4,"Status","Exited"),"YM") & " months" -> 2 years 2 months | AL10: 60s | AN10: 19
B11: Active | C11: 667 | K11: Contract End | L11: 36 | O11: 2019 | P11: 96 | R11: 2019 | S11: 11 | V11: Q3 2019 | W11: =DATE(2019,9,30) -> 43738 | X11: =DATE(2019,7,1) -> 43647 | Y11: =COUNTIFS(EmployeeData[Join Date], "<="&W11, EmployeeData[Exit Date], ">"&W11) + COUNTIFS(EmployeeData[Join Date], "<="&W11, EmployeeData[Exit Date], "") -> 241 | Z11: =COUNTIFS(EmployeeData[Exit Date], ">="&X11, EmployeeData[Exit Date], "<="&W11) -> 6 | AA11: =SUM(Y11,Y10)/2 -> 227 | AB11: =Z11/AA11 -> 0.026431718 | AL11: Grand Total | AM11: 667 | AN11: 414
B12: Exited | C12: 414 | K12: Relocation | L12: 36 | O12: Qtr1 | P12: 30 | R12: Qtr1 | V12: Q4 2019 | W12: =DATE(2019,12,31) -> 43830 | X12: =DATE(2019,10,1) -> 43739 | Y12: =COUNTIFS(EmployeeData[Join Date], "<="&W12, EmployeeData[Exit Date], ">"&W12) + COUNTIFS(EmployeeData[Join Date], "<="&W12, EmployeeData[Exit Date], "") -> 277 | Z12: =COUNTIFS(EmployeeData[Exit Date], ">="&X12, EmployeeData[Exit Date], "<="&W12) -> 4 | AA12: =SUM(Y12,Y11)/2 -> 259 | AB12: =Z12/AA12 -> 0.015444015 | AE12: Exited Tenure | AH12: Active Tenure
B13: Grand Total | C13: 1081 | K13: Grand Total | L13: 414 | O13: Qtr2 | P13: 14 | R13: Qtr2 | S13: 1 | V13: Q1 2020 | W13: =DATE(2020,3,31) -> 43921 | X13: =DATE(2020,1,1) -> 43831 | Y13: =COUNTIFS(EmployeeData[Join Date], "<="&W13, EmployeeData[Exit Date], ">"&W13) + COUNTIFS(EmployeeData[Join Date], "<="&W13, EmployeeData[Exit Date], "") -> 300 | Z13: =COUNTIFS(EmployeeData[Exit Date], ">="&X13, EmployeeData[Exit Date], "<="&W13) -> 9 | AA13: =SUM(Y13,Y12)/2 -> 288.5 | AB13: =Z13/AA13 -> 0.031195841 | AE13: Tenure (years) | AF13: Exited | AH13: Tenure (years) | AI13: Active
O14: Qtr3 | P14: 25 | R14: Qtr3 | S14: 6 | V14: Q2 2020 | W14: =DATE(2020,6,30) -> 44012 | X14: =DATE(2020,4,1) -> 43922 | Y14: =COUNTIFS(EmployeeData[Join Date], "<="&W14, EmployeeData[Exit Date], ">"&W14) + COUNTIFS(EmployeeData[Join Date], "<="&W14, EmployeeData[Exit Date], "") -> 323 | Z14: =COUNTIFS(EmployeeData[Exit Date], ">="&X14, EmployeeData[Exit Date], "<="&W14) -> 7 | AA14: =SUM(Y14,Y13)/2 -> 311.5 | AB14: =Z14/AA14 -> 0.02247191 | AE14: 0 | AF14: 121 | AH14: 0 | AI14: 42
B15: Turnover Rate: | C15: =GETPIVOTDATA("Employee ID",$B$10,"Status","Exited")/GETPIVOTDATA("Employee ID",$B$10) -> 0.38297872 | O15: Qtr4 | P15: 27 | R15: Qtr4 | S15: 4 | V15: Q3 2020 | W15: =DATE(2020,9,30) -> 44104 | X15: =DATE(2020,7,1) -> 44013 | Y15: =COUNTIFS(EmployeeData[Join Date], "<="&W15, EmployeeData[Exit Date], ">"&W15) + COUNTIFS(EmployeeData[Join Date], "<="&W15, EmployeeData[Exit Date], "") -> 356 | Z15: =COUNTIFS(EmployeeData[Exit Date], ">="&X15, EmployeeData[Exit Date], "<="&W15) -> 5 | AA15: =SUM(Y15,Y14)/2 -> 339.5 | AB15: =Z15/AA15 -> 0.014727541 | AE15: 1 | AF15: 100 | AH15: 1 | AI15: 79
O16: 2020 | P16: 80 | R16: 2020 | S16: 23 | V16: Q4 2020 | W16: =DATE(2020,12,31) -> 44196 | X16: =DATE(2020,10,1) -> 44105 | Y16: =COUNTIFS(EmployeeData[Join Date], "<="&W16, EmployeeData[Exit Date], ">"&W16) + COUNTIFS(EmployeeData[Join Date], "<="&W16, EmployeeData[Exit Date], "") -> 382 | Z16: =COUNTIFS(EmployeeData[Exit Date], ">="&X16, EmployeeData[Exit Date], "<="&W16) -> 2 | AA16: =SUM(Y16,Y15)/2 -> 369 | AB16: =Z16/AA16 -> 0.0054200542 | AE16: 2 | AF16: 76 | AH16: 2 | AI16: 80
B17: TURNOVER PER DEPARTMENT | O17: Qtr1 | P17: 21 | R17: Qtr1 | S17: 9 | V17: Q1 2021 | W17: =DATE(2021,3,31) -> 44286 | X17: =DATE(2021,1,1) -> 44197 | Y17: =COUNTIFS(EmployeeData[Join Date], "<="&W17, EmployeeData[Exit Date], ">"&W17) + COUNTIFS(EmployeeData[Join Date], "<="&W17, EmployeeData[Exit Date], "") -> 412 | Z17: =COUNTIFS(EmployeeData[Exit Date], ">="&X17, EmployeeData[Exit Date], "<="&W17) -> 7 | AA17: =SUM(Y17,Y16)/2 -> 397 | AB17: =Z17/AA17 -> 0.017632242 | AE17: 3 | AF17: 46 | AH17: 3 | AI17: 80
O18: Qtr2 | P18: 24 | R18: Qtr2 | S18: 7 | V18: Q2 2021 | W18: =DATE(2021,6,30) -> 44377 | X18: =DATE(2021,4,1) -> 44287 | Y18: =COUNTIFS(EmployeeData[Join Date], "<="&W18, EmployeeData[Exit Date], ">"&W18) + COUNTIFS(EmployeeData[Join Date], "<="&W18, EmployeeData[Exit Date], "") -> 448 | Z18: =COUNTIFS(EmployeeData[Exit Date], ">="&X18, EmployeeData[Exit Date], "<="&W18) -> 3 | AA18: =SUM(Y18,Y17)/2 -> 430 | AB18: =Z18/AA18 -> 0.0069767442 | AE18: 4 | AF18: 50 | AH18: 4 | AI18: 82
B19: Count of Exits per | O19: Qtr3 | P19: 22 | R19: Qtr3 | S19: 5 | V19: Q3 2021 | W19: =DATE(2021,9,30) -> 44469 | X19: =DATE(2021,7,1) -> 44378 | Y19: =COUNTIFS(EmployeeData[Join Date], "<="&W19, EmployeeData[Exit Date], ">"&W19) + COUNTIFS(EmployeeData[Join Date], "<="&W19, EmployeeData[Exit Date], "") -> 471 | Z19: =COUNTIFS(EmployeeData[Exit Date], ">="&X19, EmployeeData[Exit Date], "<="&W19) -> 6 | AA19: =SUM(Y19,Y18)/2 -> 459.5 | AB19: =Z19/AA19 -> 0.013057671 | AE19: 5 | AF19: 21 | AH19: 5 | AI19: 83
B20: Department | C20: Exited | O20: Qtr4 | P20: 13 | R20: Qtr4 | S20: 2 | V20: Q4 2021 | W20: =DATE(2021,12,31) -> 44561 | X20: =DATE(2021,10,1) -> 44470 | Y20: =COUNTIFS(EmployeeData[Join Date], "<="&W20, EmployeeData[Exit Date], ">"&W20) + COUNTIFS(EmployeeData[Join Date], "<="&W20, EmployeeData[Exit Date], "") -> 492 | Z20: =COUNTIFS(EmployeeData[Exit Date], ">="&X20, EmployeeData[Exit Date], "<="&W20) -> 8 | AA20: =SUM(Y20,Y19)/2 -> 481.5 | AB20: =Z20/AA20 -> 0.016614746 | AE20: Grand Total | AF20: 414 | AH20: 6 | AI20: 96
B21: Customer Support | C21: 100 | O21: 2021 | P21: 87 | R21: 2021 | S21: 24 | V21: Q1 2022 | W21: =DATE(2022,3,31) -> 44651 | X21: =DATE(2022,1,1) -> 44562 | Y21: =COUNTIFS(EmployeeData[Join Date], "<="&W21, EmployeeData[Exit Date], ">"&W21) + COUNTIFS(EmployeeData[Join Date], "<="&W21, EmployeeData[Exit Date], "") -> 519 | Z21: =COUNTIFS(EmployeeData[Exit Date], ">="&X21, EmployeeData[Exit Date], "<="&W21) -> 7 | AA21: =SUM(Y21,Y20)/2 -> 505.5 | AB21: =Z21/AA21 -> 0.013847676 | AH21: 7 | AI21: 91
B22: IT | C22: 96 | O22: Qtr1 | P22: 24 | R22: Qtr1 | S22: 7 | V22: Q2 2022 | W22: =DATE(2022,6,30) -> 44742 | X22: =DATE(2022,4,1) -> 44652 | Y22: =COUNTIFS(EmployeeData[Join Date], "<="&W22, EmployeeData[Exit Date], ">"&W22) + COUNTIFS(EmployeeData[Join Date], "<="&W22, EmployeeData[Exit Date], "") -> 541 | Z22: =COUNTIFS(EmployeeData[Exit Date], ">="&X22, EmployeeData[Exit Date], "<="&W22) -> 15 | AA22: =SUM(Y22,Y21)/2 -> 530 | AB22: =Z22/AA22 -> 0.028301887 | AH22: 8 | AI22: 34
B23: Marketing | C23: 71 | O23: Qtr2 | P23: 27 | R23: Qtr2 | S23: 3 | V23: Q3 2022 | W23: =DATE(2022,9,30) -> 44834 | X23: =DATE(2022,7,1) -> 44743 | Y23: =COUNTIFS(EmployeeData[Join Date], "<="&W23, EmployeeData[Exit Date], ">"&W23) + COUNTIFS(EmployeeData[Join Date], "<="&W23, EmployeeData[Exit Date], "") -> 561 | Z23: =COUNTIFS(EmployeeData[Exit Date], ">="&X23, EmployeeData[Exit Date], "<="&W23) -> 13 | AA23: =SUM(Y23,Y22)/2 -> 551 | AB23: =Z23/AA23 -> 0.023593466 | AH23: Grand Total | AI23: 667
B24: HR | C24: 58 | O24: Qtr3 | P24: 17 | R24: Qtr3 | S24: 6 | V24: Q4 2022 | W24: =DATE(2022,12,31) -> 44926 | X24: =DATE(2022,10,1) -> 44835 | Y24: =COUNTIFS(EmployeeData[Join Date], "<="&W24, EmployeeData[Exit Date], ">"&W24) + COUNTIFS(EmployeeData[Join Date], "<="&W24, EmployeeData[Exit Date], "") -> 583 | Z24: =COUNTIFS(EmployeeData[Exit Date], ">="&X24, EmployeeData[Exit Date], "<="&W24) -> 14 | AA24: =SUM(Y24,Y23)/2 -> 572 | AB24: =Z24/AA24 -> 0.024475524
B25: Sales | C25: 46 | O25: Qtr4 | P25: 19 | R25: Qtr4 | S25: 8 | V25: Q1 2023 | W25: =DATE(2023,3,31) -> 45016 | X25: =DATE(2023,1,1) -> 44927 | Y25: =COUNTIFS(EmployeeData[Join Date], "<="&W25, EmployeeData[Exit Date], ">"&W25) + COUNTIFS(EmployeeData[Join Date], "<="&W25, EmployeeData[Exit Date], "") -> 598 | Z25: =COUNTIFS(EmployeeData[Exit Date], ">="&X25, EmployeeData[Exit Date], "<="&W25) -> 13 | AA25: =SUM(Y25,Y24)/2 -> 590.5 | AB25: =Z25/AA25 -> 0.022015241
B26: Finance | C26: 43 | O26: 2022 | P26: 83 | R26: 2022 | S26: 49 | V26: Q2 2023 | W26: =DATE(2023,6,30) -> 45107 | X26: =DATE(2023,4,1) -> 45017 | Y26: =COUNTIFS(EmployeeData[Join Date], "<="&W26, EmployeeData[Exit Date], ">"&W26) + COUNTIFS(EmployeeData[Join Date], "<="&W26, EmployeeData[Exit Date], "") -> 624 | Z26: =COUNTIFS(EmployeeData[Exit Date], ">="&X26, EmployeeData[Exit Date], "<="&W26) -> 11 | AA26: =SUM(Y26,Y25)/2 -> 611 | AB26: =Z26/AA26 -> 0.018003273
O27: Qtr1 | P27: 26 | R27: Qtr1 | S27: 7 | V27: Q3 2023 | W27: =DATE(2023,9,30) -> 45199 | X27: =DATE(2023,7,1) -> 45108 | Y27: =COUNTIFS(EmployeeData[Join Date], "<="&W27, EmployeeData[Exit Date], ">"&W27) + COUNTIFS(EmployeeData[Join Date], "<="&W27, EmployeeData[Exit Date], "") -> 646 | Z27: =COUNTIFS(EmployeeData[Exit Date], ">="&X27, EmployeeData[Exit Date], "<="&W27) -> 15 | AA27: =SUM(Y27,Y26)/2 -> 635 | AB27: =Z27/AA27 -> 0.023622047
B28: EMPLOYEE HEADCOUNT YoY | O28: Qtr2 | P28: 16 | R28: Qtr2 | S28: 15 | V28: Q4 2023 | W28: =DATE(2023,12,31) -> 45291 | X28: =DATE(2023,10,1) -> 45200 | Y28: =COUNTIFS(EmployeeData[Join Date], "<="&W28, EmployeeData[Exit Date], ">"&W28) + COUNTIFS(EmployeeData[Join Date], "<="&W28, EmployeeData[Exit Date], "") -> 664 | Z28: =COUNTIFS(EmployeeData[Exit Date], ">="&X28, EmployeeData[Exit Date], "<="&W28) -> 20 | AA28: =SUM(Y28,Y27)/2 -> 655 | AB28: =Z28/AA28 -> 0.030534351
O29: Qtr3 | P29: 18 | R29: Qtr3 | S29: 13 | V29: Q1 2024 | W29: =DATE(2024,3,31) -> 45382 | X29: =DATE(2024,1,1) -> 45292 | Y29: =COUNTIFS(EmployeeData[Join Date], "<="&W29, EmployeeData[Exit Date], ">"&W29) + COUNTIFS(EmployeeData[Join Date], "<="&W29, EmployeeData[Exit Date], "") -> 674 | Z29: =COUNTIFS(EmployeeData[Exit Date], ">="&X29, EmployeeData[Exit Date], "<="&W29) -> 18 | AA29: =SUM(Y29,Y28)/2 -> 669 | AB29: =Z29/AA29 -> 0.02690583
B30: Year | C30: Headcount | D30: Total Exits | E30: Total Headcount | F30: Ave. Headcount | G30: Headcount YoY | H30: Turnover Rate | O30: Qtr4 | P30: 23 | R30: Qtr4 | S30: 14 | V30: Q2 2024 | W30: =DATE(2024,6,30) -> 45473 | X30: =DATE(2024,4,1) -> 45383 | Y30: =COUNTIFS(EmployeeData[Join Date], "<="&W30, EmployeeData[Exit Date], ">"&W30) + COUNTIFS(EmployeeData[Join Date], "<="&W30, EmployeeData[Exit Date], "") -> 688 | Z30: =COUNTIFS(EmployeeData[Exit Date], ">="&X30, EmployeeData[Exit Date], "<="&W30) -> 16 | AA30: =SUM(Y30,Y29)/2 -> 681 | AB30: =Z30/AA30 -> 0.02349486
B31: 2018 | C31: 146 | D31: 3 | E31: =C31-D31 -> 143 | F31: =E31 -> 143 | G31: 1 | H31: =D31/F31 -> 0.020979021 | O31: 2023 | P31: 84 | R31: 2023 | S31: 59 | V31: Q3 2024 | W31: =DATE(2024,9,30) -> 45565 | X31: =DATE(2024,7,1) -> 45474 | Y31: =COUNTIFS(EmployeeData[Join Date], "<="&W31, EmployeeData[Exit Date], ">"&W31) + COUNTIFS(EmployeeData[Join Date], "<="&W31, EmployeeData[Exit Date], "") -> 701 | Z31: =COUNTIFS(EmployeeData[Exit Date], ">="&X31, EmployeeData[Exit Date], "<="&W31) -> 16 | AA31: =SUM(Y31,Y30)/2 -> 694.5 | AB31: =Z31/AA31 -> 0.023038157
B32: 2019 | C32: 288 | D32: 11 | E32: =C32-D32 -> 277 | F32: =SUM(E32,E31)/2 -> 210 | G32: =(E32-E31)/E31 -> 0.93706294 | H32: =D32/F32 -> 0.052380952 | O32: Qtr1 | P32: 18 | R32: Qtr1 | S32: 13 | V32: Q4 2024 | W32: =DATE(2024,12,31) -> 45657 | X32: =DATE(2024,10,1) -> 45566 | Y32: =COUNTIFS(EmployeeData[Join Date], "<="&W32, EmployeeData[Exit Date], ">"&W32) + COUNTIFS(EmployeeData[Join Date], "<="&W32, EmployeeData[Exit Date], "") -> 712 | Z32: =COUNTIFS(EmployeeData[Exit Date], ">="&X32, EmployeeData[Exit Date], "<="&W32) -> 21 | AA32: =SUM(Y32,Y31)/2 -> 706.5 | AB32: =Z32/AA32 -> 0.029723992
B33: 2020 | C33: 405 | D33: 23 | E33: =C33-D33 -> 382 | F33: =SUM(E33,E32)/2 -> 329.5 | G33: =(E33-E32)/E32 -> 0.37906137 | H33: =D33/F33 -> 0.069802731 | O33: Qtr2 | P33: 22 | R33: Qtr2 | S33: 11 | V33: Q1 2025 | W33: =DATE(2025,3,31) -> 45747 | X33: =DATE(2025,1,1) -> 45658 | Y33: =COUNTIFS(EmployeeData[Join Date], "<="&W33, EmployeeData[Exit Date], ">"&W33) + COUNTIFS(EmployeeData[Join Date], "<="&W33, EmployeeData[Exit Date], "") -> 710 | Z33: =COUNTIFS(EmployeeData[Exit Date], ">="&X33, EmployeeData[Exit Date], "<="&W33) -> 31 | AA33: =SUM(Y33,Y32)/2 -> 711 | AB33: =Z33/AA33 -> 0.043600563
B34: 2021 | C34: 516 | D34: 24 | E34: =C34-D34 -> 492 | F34: =SUM(E34,E33)/2 -> 437 | G34: =(E34-E33)/E33 -> 0.28795812 | H34: =D34/F34 -> 0.054919908 | O34: Qtr3 | P34: 22 | R34: Qtr3 | S34: 15 | V34: Q2 2025 | W34: =DATE(2025,6,30) -> 45838 | X34: =DATE(2025,4,1) -> 45748 | Y34: =COUNTIFS(EmployeeData[Join Date], "<="&W34, EmployeeData[Exit Date], ">"&W34) + COUNTIFS(EmployeeData[Join Date], "<="&W34, EmployeeData[Exit Date], "") -> 720 | Z34: =COUNTIFS(EmployeeData[Exit Date], ">="&X34, EmployeeData[Exit Date], "<="&W34) -> 26 | AA34: =SUM(Y34,Y33)/2 -> 715 | AB34: =Z34/AA34 -> 0.036363636
B35: 2022 | C35: 632 | D35: 49 | E35: =C35-D35 -> 583 | F35: =SUM(E35,E34)/2 -> 537.5 | G35: =(E35-E34)/E34 -> 0.18495935 | H35: =D35/F35 -> 0.091162791 | O35: Qtr4 | P35: 22 | R35: Qtr4 | S35: 20 | V35: Q3 2025 | W35: =DATE(2025,9,30) -> 45930 | X35: =DATE(2025,7,1) -> 45839 | Y35: =COUNTIFS(EmployeeData[Join Date], "<="&W35, EmployeeData[Exit Date], ">"&W35) + COUNTIFS(EmployeeData[Join Date], "<="&W35, EmployeeData[Exit Date], "") -> 735 | Z35: =COUNTIFS(EmployeeData[Exit Date], ">="&X35, EmployeeData[Exit Date], "<="&W35) -> 22 | AA35: =SUM(Y35,Y34)/2 -> 727.5 | AB35: =Z35/AA35 -> 0.03024055
B36: 2023 | C36: 723 | D36: 59 | E36: =C36-D36 -> 664 | F36: =SUM(E36,E35)/2 -> 623.5 | G36: =(E36-E35)/E35 -> 0.13893654 | H36: =D36/F36 -> 0.094627105 | O36: 2024 | P36: 71 | R36: 2024 | S36: 71 | V36: Q4 2025 | W36: =DATE(2025,12,31) -> 46022 | X36: =DATE(2025,10,1) -> 45931 | Y36: =COUNTIFS(EmployeeData[Join Date], "<="&W36, EmployeeData[Exit Date], ">"&W36) + COUNTIFS(EmployeeData[Join Date], "<="&W36, EmployeeData[Exit Date], "") -> 725 | Z36: =COUNTIFS(EmployeeData[Exit Date], ">="&X36, EmployeeData[Exit Date], "<="&W36) -> 37 | AA36: =SUM(Y36,Y35)/2 -> 730 | AB36: =Z36/AA36 -> 0.050684932
B37: 2024 | C37: 783 | D37: 71 | E37: =C37-D37 -> 712 | F37: =SUM(E37,E36)/2 -> 688 | G37: =(E37-E36)/E36 -> 0.072289157 | H37: =D37/F37 -> 0.10319767 | O37: Qtr1 | P37: 16 | R37: Qtr1 | S37: 18 | U37: 🚩 | V37: Q1 2026 | W37: =DATE(2026,3,31) -> 46112 | X37: =DATE(2026,1,1) -> 46023 | Y37: =COUNTIFS(EmployeeData[Join Date], "<="&W37, EmployeeData[Exit Date], ">"&W37) + COUNTIFS(EmployeeData[Join Date], "<="&W37, EmployeeData[Exit Date], "") -> 689 | Z37: =COUNTIFS(EmployeeData[Exit Date], ">="&X37, EmployeeData[Exit Date], "<="&W37) -> 36 | AA37: =SUM(Y37,Y36)/2 -> 707 | AB37: =Z37/AA37 -> 0.050919378
B38: 2025 | C38: 841 | D38: 116 | E38: =C38-D38 -> 725 | F38: =SUM(E38,E37)/2 -> 718.5 | G38: =(E38-E37)/E37 -> 0.018258427 | H38: =D38/F38 -> 0.16144746 | O38: Qtr2 | P38: 20 | R38: Qtr2 | S38: 16 | U38: 🚩 | V38: Q2 2026 | W38: =DATE(2026,6,30) -> 46203 | X38: =DATE(2026,4,1) -> 46113 | Y38: =COUNTIFS(EmployeeData[Join Date], "<="&W38, EmployeeData[Exit Date], ">"&W38) + COUNTIFS(EmployeeData[Join Date], "<="&W38, EmployeeData[Exit Date], "") -> 667 | Z38: =COUNTIFS(EmployeeData[Exit Date], ">="&X38, EmployeeData[Exit Date], "<="&W38) -> 22 | AA38: =SUM(Y38,Y37)/2 -> 678 | AB38: =Z38/AA38 -> 0.032448378
B39: 2026 | C39: 725 | D39: 58 | E39: =C39-D39 -> 667 | F39: =SUM(E39,E38)/2 -> 696 | G39: =(E39-E38)/E38 -> -0.08 | H39: =D39/F39 -> 0.083333333 | O39: Qtr3 | P39: 18 | R39: Qtr3 | S39: 16
O40: Qtr4 | P40: 17 | R40: Qtr4 | S40: 21
O41: 2025 | P41: 84 | R41: 2025 | S41: 116
O42: Qtr1 | P42: 21 | R42: Qtr1 | S42: 31
...

Sheet Employee Data
A1: Employee ID | B1: Full Name | C1: Department | D1: Gender | E1: Age | F1: Age bracket | G1: Join Date | H1: Exit Date | I1: Exit Reason | J1: Status | K1: Tenure (days) | L1: Tenure (years) | Q1: Tenure (yrs. mos. days)
A2: 1001 | B2: Paz Cruz Dela Cruz | C2: Marketing | D2: Female | E2: 38 | F2: {=_xlfn.IFS(EmployeeData[[#This Row],[Age]]<30,"20s",EmployeeData[[#This Row],[Age]]<40,"30s",EmployeeData[[#This Row],[Age]]<50,"40s",EmployeeData[[#This Row],[Age]]<60,"50s",EmployeeData[[#This Row],[Age]]>=60,"60s")} -> 30s | G2: 44104 | H2: 45702 | I2: Better Opportunity | J2: Exited | K2: {=_xlfn.IFS(EmployeeData[[#This Row],[Status]]="Active",_xlfn.DAYS(TODAY(),EmployeeData[[#This Row],[Join Date]]),EmployeeData[[#This Row],[Status]]="Exited",_xlfn.DAYS(EmployeeData[[#This Row],[Exit Date]],EmployeeData[[#This Row],[Join Date]]))} -> 1598 | L2: {=_xlfn.IFS(EmployeeData[[#This Row],[Status]]="Exited",DATEDIF(EmployeeData[[#This Row],[Join Date]], EmployeeData[[#This Row],[Exit Date]], "Y"),EmployeeData[[#This Row],[Status]]="Active",DATEDIF(EmployeeData[[#This Row],[Join Date]], TODAY(), "Y"))} -> 4 | Q2: {=_xlfn.IFS(EmployeeData[[#This Row],[Status]]="Exited",DATEDIF(EmployeeData[[#This Row],[Join Date]], EmployeeData[[#This Row],[Exit Date]], "Y") & " years " & DATEDIF(EmployeeData[[#This Row],[Join Date]], EmployeeData[[#This Row],[Exit Date]], "YM") & " months " & DATEDIF(EmployeeData[[#This Row],[Join Date]], EmployeeData[[#This Row],[Exit Date]], "MD") & " days",EmployeeData[[#This Row],[Status]]="Active",DATEDIF(EmployeeData[[#This Row],[Join Date]], TODAY(), "Y") & " years " & DATEDIF(EmployeeData[[#This Row],[Join Date]], TODAY(), "YM") & " months " & DATEDIF(EmployeeData[[#This Row],[Join Date]], TODAY(), "MD") & " days")} -> 4 years 4 months 15 days
A3: 1002 | B3: Paz Aguilar Camacho | C3: Customer Support | D3: Female | E3: 53 | F3: {=_xlfn.IFS(EmployeeData[[#This Row],[Age]]<30,"20s",EmployeeData[[#This Row],[Age]]<40,"30s",EmployeeData[[#This Row],[Age]]<50,"40s",EmployeeData[[#This Row],[Age]]<60,"50s",EmployeeData[[#This Row],[Age]]>=60,"60s")} -> 50s | G3: 45566 | H3: 45859 | I3: Personal Reasons | J3: Exited | K3: {=_xlfn.IFS(EmployeeData[[#This Row],[Status]]="Active",_xlfn.DAYS(TODAY(),EmployeeData[[#This Row],[Join Date]]),EmployeeData[[#This Row],[Status]]="Exited",_xlfn.DAYS(EmployeeData[[#This Row],[Exit Date]],EmployeeData[[#This Row],[Join Date]]))} -> 293 | L3: {=_xlfn.IFS(EmployeeData[[#This Row],[Status]]="Exited",DATEDIF(EmployeeData[[#This Row],[Join Date]], EmployeeData[[#This Row],[Exit Date]], "Y"),EmployeeData[[#This Row],[Status]]="Active",DATEDIF(EmployeeData[[#This Row],[Join Date]], TODAY(), "Y"))} -> 0 | Q3: {=_xlfn.IFS(EmployeeData[[#This Row],[Status]]="Exited",DATEDIF(EmployeeData[[#This Row],[Join Date]], EmployeeData[[#This Row],[Exit Date]], "Y") & " years " & DATEDIF(EmployeeData[[#This Row],[Join Date]], EmployeeData[[#This Row],[Exit Date]], "YM") & " months " & DATEDIF(EmployeeData[[#This Row],[Join Date]], EmployeeData[[#This Row],[Exit Date]], "MD") & " days",EmployeeData[[#This Row],[Status]]="Active",DATEDIF(EmployeeData[[#This Row],[Join Date]], TODAY(), "Y") & " years " & DATEDIF(EmployeeData[[#This Row],[Join Date]], TODAY(), "YM") & " months " & DATEDIF(EmployeeData[[#This Row],[Join Date]], TODAY(), "MD") & " days")} -> 0 years 9 months 20 days
A4: 1003 | B4: Celine Diaz Domingo | C4: Sales | D4: Female | E4: 31 | F4: {=_xlfn.IFS(EmployeeData[[#This Row],[Age]]<30,"20s",EmployeeData[[#This Row],[Age]]<40,"30s",EmployeeData[[#This Row],[Age]]<50,"40s",EmployeeData[[#This Row],[Age]]<60,"50s",EmployeeData[[#This Row],[Age]]>=60,"60s")} -> 30s | G4: 45960 | J4: Active | K4: {=_xlfn.IFS(EmployeeData[[#This Row],[Status]]="Active",_xlfn.DAYS(TODAY(),EmployeeData[[#This Row],[Join Date]]),EmployeeData[[#This Row],[Status]]="Exited",_xlfn.DAYS(EmployeeData[[#This Row],[Exit Date]],EmployeeData[[#This Row],[Join Date]]))} -> 237 | L4: {=_xlfn.IFS(EmployeeData[[#This Row],[Status]]="Exited",DATEDIF(EmployeeData[[#This Row],[Join Date]], EmployeeData[[#This Row],[Exit Date]], "Y"),EmployeeData[[#This Row],[Status]]="Active",DATEDIF(EmployeeData[[#This Row],[Join Date]], TODAY(), "Y"))} -> 0 | Q4: {=_xlfn.IFS(EmployeeData[[#This Row],[Status]]="Exited",DATEDIF(EmployeeData[[#This Row],[Join Date]], EmployeeData[[#This Row],[Exit Date]], "Y") & " years " & DATEDIF(EmployeeData[[#This Row],[Join Date]], EmployeeData[[#This Row],[Exit Date]], "YM") & " months " & DATEDIF(EmployeeData[[#This Row],[Join Date]], EmployeeData[[#This Row],[Exit Date]], "MD") & " days",EmployeeData[[#This Row],[Status]]="Active",DATEDIF(EmployeeData[[#This Row],[Join Date]], TODAY(), "Y") & " years " & DATEDIF(EmployeeData[[#This Row],[Join Date]], TODAY(), "YM") & " months " & DATEDIF(EmployeeData[[#This Row],[Join Date]], TODAY(), "MD") & " days")} -> 0 years 7 months 25 days
A5: 1004 | B5: Eduardo Torres Dela Torre | C5: Customer Support | D5: Male | E5: 43 | F5: {=_xlfn.IFS(EmployeeData[[#This Row],[Age]]<30,"20s",EmployeeData[[#This Row],[Age]]<40,"30s",EmployeeData[[#This Row],[Age]]<50,"40s",EmployeeData[[#This Row],[Age]]<60,"50s",EmployeeData[[#This Row],[Age]]>=60,"60s")} -> 40s | G5: 44509 | J5: Active | K5: {=_xlfn.IFS(EmployeeData[[#This Row],[Status]]="Active",_xlfn.DAYS(TODAY(),EmployeeData[[#This Row],[Join Date]]),EmployeeData[[#This Row],[Status]]="Exited",_xlfn.DAYS(EmployeeData[[#This Row],[Exit Date]],EmployeeData[[#This Row],[Join Date]]))} -> 1688 | L5: {=_xlfn.IFS(EmployeeData[[#This Row],[Status]]="Exited",DATEDIF(EmployeeData[[#This Row],[Join Date]], EmployeeData[[#This Row],[Exit Date]], "Y"),EmployeeData[[#This Row],[Status]]="Active",DATEDIF(EmployeeData[[#This Row],[Join Date]], TODAY(), "Y"))} -> 4 | Q5: {=_xlfn.IFS(EmployeeData[[#This Row],[Status]]="Exited",DATEDIF(EmployeeData[[#This Row],[Join Date]], EmployeeData[[#This Row],[Exit Date]], "Y") & " years " & DATEDIF(EmployeeData[[#This Row],[Join Date]], EmployeeData[[#This Row],[Exit Date]], "YM") & " months " & DATEDIF(EmployeeData[[#This Row],[Join Date]], EmployeeData[[#This Row],[Exit Date]], "MD") & " days",EmployeeData[[#This Row],[Status]]="Active",DATEDIF(EmployeeData[[#This Row],[Join Date]], TODAY(), "Y") & " years " & DATEDIF(EmployeeData[[#This Row],[Join Date]], TODAY(), "YM") & " months " & DATEDIF(EmployeeData[[#This Row],[Join Date]], TODAY(), "MD") & " days")} -> 4 years 7 months 15 days
A6: 1005 | B6: Jerome Ocampo Macapagal | C6: Finance | D6: Male | E6: 56 | F6: {=_xlfn.IFS(EmployeeData[[#This Row],[Age]]<30,"20s",EmployeeData[[#This Row],[Age]]<40,"30s",EmployeeData[[#This Row],[Age]]<50,"40s",EmployeeData[[#This Row],[Age]]<60,"50s",EmployeeData[[#This Row],[Age]]>=60,"60s")} -> 50s | G6: 44301 | J6: Active | K6: {=_xlfn.IFS(EmployeeData[[#This Row],[Status]]="Active",_xlfn.DAYS(TODAY(),EmployeeData[[#This Row],[Join Date]]),EmployeeData[[#This Row],[Status]]="Exited",_xlfn.DAYS(EmployeeData[[#This Row],[Exit Date]],EmployeeData[[#This Row],[Join Date]]))} -> 1896 | L6: {=_xlfn.IFS(EmployeeData[[#This Row],[Status]]="Exited",DATEDIF(EmployeeData[[#This Row],[Join Date]], EmployeeData[[#This Row],[Exit Date]], "Y"),EmployeeData[[#This Row],[Status]]="Active",DATEDIF(EmployeeData[[#This Row],[Join Date]], TODAY(), "Y"))} -> 5 | Q6: {=_xlfn.IFS(EmployeeData[[#This Row],[Status]]="Exited",DATEDIF(EmployeeData[[#This Row],[Join Date]], EmployeeData[[#This Row],[Exit Date]], "Y") & " years " & DATEDIF(EmployeeData[[#This Row],[Join Date]], EmployeeData[[#This Row],[Exit Date]], "YM") & " months " & DATEDIF(EmployeeData[[#This Row],[Join Date]], EmployeeData[[#This Row],[Exit Date]], "MD") & " days",EmployeeData[[#This Row],[Status]]="Active",DATEDIF(EmployeeData[[#This Row],[Join Date]], TODAY(), "Y") & " years " & DATEDIF(EmployeeData[[#This Row],[Join Date]], TODAY(), "YM") & " months " & DATEDIF(EmployeeData[[#This Row],[Join Date]], TODAY(), "MD") & " days")} -> 5 years 2 months 9 days
A7: 1006 | B7: Lourdes Santiago Panganiban | C7: Customer Support | D7: Female | E7: 39 | F7: {=_xlfn.IFS(EmployeeData[[#This Row],[Age]]<30,"20s",EmployeeData[[#This Row],[Age]]<40,"30s",EmployeeData[[#This Row],[Age]]<50,"40s",EmployeeData[[#This Row],[Age]]<60,"50s",EmployeeData[[#This Row],[Age]]>=60,"60s")} -> 30s | G7: 43427 | J7: Active | K7: {=_xlfn.IFS(EmployeeData[[#This Row],[Status]]="Active",_xlfn.DAYS(TODAY(),EmployeeData[[#This Row],[Join Date]]),EmployeeData[[#This Row],[Status]]="Exited",_xlfn.DAYS(EmployeeData[[#This Row],[Exit Date]],EmployeeData[[#This Row],[Join Date]]))} -> 2770 | L7: {=_xlfn.IFS(EmployeeData[[#This Row],[Status]]="Exited",DATEDIF(EmployeeData[[#This Row],[Join Date]], EmployeeData[[#This Row],[Exit Date]], "Y"),EmployeeData[[#This Row],[Status]]="Active",DATEDIF(EmployeeData[[#This Row],[Join Date]], TODAY(), "Y"))} -> 7 | Q7: {=_xlfn.IFS(EmployeeData[[#This Row],[Status]]="Exited",DATEDIF(EmployeeData[[#This Row],[Join Date]], EmployeeData[[#This Row],[Exit Date]], "Y") & " years " & DATEDIF(EmployeeData[[#This Row],[Join Date]], EmployeeData[[#This Row],[Exit Date]], "YM") & " months " & DATEDIF(EmployeeData[[#This Row],[Join Date]], EmployeeData[[#This Row],[Exit Date]], "MD") & " days",EmployeeData[[#This Row],[Status]]="Active",DATEDIF(EmployeeData[[#This Row],[Join Date]], TODAY(), "Y") & " years " & DATEDIF(EmployeeData[[#This Row],[Join Date]], TODAY(), "YM") & " months " & DATEDIF(EmployeeData[[#This Row],[Join Date]], TODAY(), "MD") & " days")} -> 7 years 7 months 1 days
A8: 1007 | B8: Manuel Quiambao | C8: Customer Support | D8: Male | E8: 38 | F8: {=_xlfn.IFS(EmployeeData[[#This Row],[Age]]<30,"20s",EmployeeData[[#This Row],[Age]]<40,"30s",EmployeeData[[#This Row],[Age]]<50,"40s",EmployeeData[[#This Row],[Age]]<60,"50s",EmployeeData[[#This Row],[Age]]>=60,"60s")} -> 30s | G8: 45975 | J8: Active | K8: {=_xlfn.IFS(EmployeeData[[#This Row],[Status]]="Active",_xlfn.DAYS(TODAY(),EmployeeData[[#This Row],[Join Date]]),EmployeeData[[#This Row],[Status]]="Exited",_xlfn.DAYS(EmployeeData[[#This Row],[Exit Date]],EmployeeData[[#This Row],[Join Date]]))} -> 222 | L8: {=_xlfn.IFS(EmployeeData[[#This Row],[Status]]="Exited",DATEDIF(EmployeeData[[#This Row],[Join Date]], EmployeeData[[#This Row],[Exit Date]], "Y"),EmployeeData[[#This Row],[Status]]="Active",DATEDIF(EmployeeData[[#This Row],[Join Date]], TODAY(), "Y"))} -> 0 | Q8: {=_xlfn.IFS(EmployeeData[[#This Row],[Status]]="Exited",DATEDIF(EmployeeData[[#This Row],[Join Date]], EmployeeData[[#This Row],[Exit Date]], "Y") & " years " & DATEDIF(EmployeeData[[#This Row],[Join Date]], EmployeeData[[#This Row],[Exit Date]], "YM") & " months " & DATEDIF(EmployeeData[[#This Row],[Join Date]], EmployeeData[[#This Row],[Exit Date]], "MD") & " days",EmployeeData[[#This Row],[Status]]="Active",DATEDIF(EmployeeData[[#This Row],[Join Date]], TODAY(), "Y") & " years " & DATEDIF(EmployeeData[[#This Row],[Join Date]], TODAY(), "YM") & " months " & DATEDIF(EmployeeData[[#This Row],[Join Date]], TODAY(), "MD") & " days")} -> 0 years 7 months 10 days
A9: 1008 | B9: Pacita Bautista Guevarra | C9: Marketing | D9: Female | E9: 50 | F9: {=_xlfn.IFS(EmployeeData[[#This Row],[Age]]<30,"20s",EmployeeData[[#This Row],[Age]]<40,"30s",EmployeeData[[#This Row],[Age]]<50,"40s",EmployeeData[[#This Row],[Age]]<60,"50s",EmployeeData[[#This Row],[Age]]>=60,"60s")} -> 50s | G9: 44655 | H9: 46055 | I9: Personal Reasons | J9: Exited | K9: {=_xlfn.IFS(EmployeeData[[#This Row],[Status]]="Active",_xlfn.DAYS(TODAY(),EmployeeData[[#This Row],[Join Date]]),EmployeeData[[#This Row],[Status]]="Exited",_xlfn.DAYS(EmployeeData[[#This Row],[Exit Date]],EmployeeData[[#This Row],[Join Date]]))} -> 1400 | L9: {=_xlfn.IFS(EmployeeData[[#This Row],[Status]]="Exited",DATEDIF(EmployeeData[[#This Row],[Join Date]], EmployeeData[[#This Row],[Exit Date]], "Y"),EmployeeData[[#This Row],[Status]]="Active",DATEDIF(EmployeeData[[#This Row],[Join Date]], TODAY(), "Y"))} -> 3 | Q9: {=_xlfn.IFS(EmployeeData[[#This Row],[Status]]="Exited",DATEDIF(EmployeeData[[#This Row],[Join Date]], EmployeeData[[#This Row],[Exit Date]], "Y") & " years " & DATEDIF(EmployeeData[[#This Row],[Join Date]], EmployeeData[[#This Row],[Exit Date]], "YM") & " months " & DATEDIF(EmployeeData[[#This Row],[Join Date]], EmployeeData[[#This Row],[Exit Date]], "MD") & " days",EmployeeData[[#This Row],[Status]]="Active",DATEDIF(EmployeeData[[#This Row],[Join Date]], TODAY(), "Y") & " years " & DATEDIF(EmployeeData[[#This Row],[Join Date]], TODAY(), "YM") & " months " & DATEDIF(EmployeeData[[#This Row],[Join Date]], TODAY(), "MD") & " days")} -> 3 years 9 months 29 days
A10: 1009 | B10: Tess Ang Miranda | C10: Customer Support | D10: Female | E10: 41 | F10: {=_xlfn.IFS(EmployeeData[[#This Row],[Age]]<30,"20s",EmployeeData[[#This Row],[Age]]<40,"30s",EmployeeData[[#This Row],[Age]]<50,"40s",EmployeeData[[#This Row],[Age]]<60,"50s",EmployeeData[[#This Row],[Age]]>=60,"60s")} -> 40s | G10: 44744 | H10: 45266 | I10: Resignation | J10: Exited | K10: {=_xlfn.IFS(EmployeeData[[#This Row],[Status]]="Active",_xlfn.DAYS(TODAY(),EmployeeData[[#This Row],[Join Date]]),EmployeeData[[#This Row],[Status]]="Exited",_xlfn.DAYS(EmployeeData[[#This Row],[Exit Date]],EmployeeData[[#This Row],[Join Date]]))} -> 522 | L10: {=_xlfn.IFS(EmployeeData[[#This Row],[Status]]="Exited",DATEDIF(EmployeeData[[#This Row],[Join Date]], EmployeeData[[#This Row],[Exit Date]], "Y"),EmployeeData[[#This Row],[Status]]="Active",DATEDIF(EmployeeData[[#This Row],[Join Date]], TODAY(), "Y"))} -> 1 | Q10: {=_xlfn.IFS(EmployeeData[[#This Row],[Status]]="Exited",DATEDIF(EmployeeData[[#This Row],[Join Date]], EmployeeData[[#This Row],[Exit Date]], "Y") & " years " & DATEDIF(EmployeeData[[#This Row],[Join Date]], EmployeeData[[#This Row],[Exit Date]], "YM") & " months " & DATEDIF(EmployeeData[[#This Row],[Join Date]], EmployeeData[[#This Row],[Exit Date]], "MD") & " days",EmployeeData[[#This Row],[Status]]="Active",DATEDIF(EmployeeData[[#This Row],[Join Date]], TODAY(), "Y") & " years " & DATEDIF(EmployeeData[[#This Row],[Join Date]], TODAY(), "YM") & " months " & DATEDIF(EmployeeData[[#This Row],[Join Date]], TODAY(), "MD") & " days")} -> 1 years 5 months 4 days
A11: 1010 | B11: Gloria Chan | C11: IT | D11: Other | E11: 50 | F11: {=_xlfn.IFS(EmployeeData[[#This Row],[Age]]<30,"20s",EmployeeData[[#This Row],[Age]]<40,"30s",EmployeeData[[#This Row],[Age]]<50,"40s",EmployeeData[[#This Row],[Age]]<60,"50s",EmployeeData[[#This Row],[Age]]>=60,"60s")} -> 50s | G11: 43686 | H11: 44786 | I11: Personal Reasons | J11: Exited | K11: {=_xlfn.IFS(EmployeeData[[#This Row],[Status]]="Active",_xlfn.DAYS(TODAY(),EmployeeData[[#This Row],[Join Date]]),EmployeeData[[#This Row],[Status]]="Exited",_xlfn.DAYS(EmployeeData[[#This Row],[Exit Date]],EmployeeData[[#This Row],[Join Date]]))} -> 1100 | L11: {=_xlfn.IFS(EmployeeData[[#This Row],[Status]]="Exited",DATEDIF(EmployeeData[[#This Row],[Join Date]], EmployeeData[[#This Row],[Exit Date]], "Y"),EmployeeData[[#This Row],[Status]]="Active",DATEDIF(EmployeeData[[#This Row],[Join Date]], TODAY(), "Y"))} -> 3 | Q11: {=_xlfn.IFS(EmployeeData[[#This Row],[Status]]="Exited",DATEDIF(EmployeeData[[#This Row],[Join Date]], EmployeeData[[#This Row],[Exit Date]], "Y") & " years " & DATEDIF(EmployeeData[[#This Row],[Join Date]], EmployeeData[[#This Row],[Exit Date]], "YM") & " months " & DATEDIF(EmployeeData[[#This Row],[Join Date]], EmployeeData[[#This Row],[Exit Date]], "MD") & " days",EmployeeData[[#This Row],[Status]]="Active",DATEDIF(EmployeeData[[#This Row],[Join Date]], TODAY(), "Y") & " years " & DATEDIF(EmployeeData[[#This Row],[Join Date]], TODAY(), "YM") & " months " & DATEDIF(EmployeeData[[#This Row],[Join Date]], TODAY(), "MD") & " days")} -> 3 years 0 months 4 days
A12: 1011 | B12: Crisanto Bautista Cueto | C12: IT | D12: Male | E12: 44 | F12: {=_xlfn.IFS(EmployeeData[[#This Row],[Age]]<30,"20s",EmployeeData[[#This Row],[Age]]<40,"30s",EmployeeData[[#This Row],[Age]]<50,"40s",EmployeeData[[#This Row],[Age]]<60,"50s",EmployeeData[[#This Row],[Age]]>=60,"60s")} -> 40s | G12: 43999 | J12: Active | K12: {=_xlfn.IFS(EmployeeData[[#This Row],[Status]]="Active",_xlfn.DAYS(TODAY(),EmployeeData[[#This Row],[Join Date]]),EmployeeData[[#This Row],[Status]]="Exited",_xlfn.DAYS(EmployeeData[[#This Row],[Exit Date]],EmployeeData[[#This Row],[Join Date]]))} -> 2198 | L12: {=_xlfn.IFS(EmployeeData[[#This Row],[Status]]="Exited",DATEDIF(EmployeeData[[#This Row],[Join Date]], EmployeeData[[#This Row],[Exit Date]], "Y"),EmployeeData[[#This Row],[Status]]="Active",DATEDIF(EmployeeData[[#This Row],[Join Date]], TODAY(), "Y"))} -> 6 | Q12: {=_xlfn.IFS(EmployeeData[[#This Row],[Status]]="Exited",DATEDIF(EmployeeData[[#This Row],[Join Date]], EmployeeData[[#This Row],[Exit Date]], "Y") & " years " & DATEDIF(EmployeeData[[#This Row],[Join Date]], EmployeeData[[#This Row],[Exit Date]], "YM") & " months " & DATEDIF(EmployeeData[[#This Row],[Join Date]], EmployeeData[[#This Row],[Exit Date]], "MD") & " days",EmployeeData[[#This Row],[Status]]="Active",DATEDIF(EmployeeData[[#This Row],[Join Date]], TODAY(), "Y") & " years " & DATEDIF(EmployeeData[[#This Row],[Join Date]], TODAY(), "YM") & " months " & DATEDIF(EmployeeData[[#This Row],[Join Date]], TODAY(), "MD") & " days")} -> 6 years 0 months 7 days
A13: 1012 | B13: Teresa Go Salazar | C13: Sales | D13: Female | E13: 31 | F13: {=_xlfn.IFS(EmployeeData[[#This Row],[Age]]<30,"20s",EmployeeData[[#This Row],[Age]]<40,"30s",EmployeeData[[#This Row],[Age]]<50,"40s",EmployeeData[[#This Row],[Age]]<60,"50s",EmployeeData[[#This Row],[Age]]>=60,"60s")} -> 30s | G13: 45888 | J13: Active | K13: {=_xlfn.IFS(EmployeeData[[#This Row],[Status]]="Active",_xlfn.DAYS(TODAY(),EmployeeData[[#This Row],[Join Date]]),EmployeeData[[#This Row],[Status]]="Exited",_xlfn.DAYS(EmployeeData[[#This Row],[Exit Date]],EmployeeData[[#This Row],[Join Date]]))} -> 309 | L13: {=_xlfn.IFS(EmployeeData[[#This Row],[Status]]="Exited",DATEDIF(EmployeeData[[#This Row],[Join Date]], EmployeeData[[#This Row],[Exit Date]], "Y"),EmployeeData[[#This Row],[Status]]="Active",DATEDIF(EmployeeData[[#This Row],[Join Date]], TODAY(), "Y"))} -> 0 | Q13: {=_xlfn.IFS(EmployeeData[[#This Row],[Status]]="Exited",DATEDIF(EmployeeData[[#This Row],[Join Date]], EmployeeData[[#This Row],[Exit Date]], "Y") & " years " & DATEDIF(EmployeeData[[#This Row],[Join Date]], EmployeeData[[#This Row],[Exit Date]], "YM") & " months " & DATEDIF(EmployeeData[[#This Row],[Join Date]], EmployeeData[[#This Row],[Exit Date]], "MD") & " days",EmployeeData[[#This Row],[Status]]="Active",DATEDIF(EmployeeData[[#This Row],[Join Date]], TODAY(), "Y") & " years " & DATEDIF(EmployeeData[[#This Row],[Join Date]], TODAY(), "YM") & " months " & DATEDIF(EmployeeData[[#This Row],[Join Date]], TODAY(), "MD") & " days")} -> 0 years 10 months 5 days
A14: 1013 | B14: Gloria Wong | C14: Marketing | D14: Other | E14: 21 | F14: {=_xlfn.IFS(EmployeeData[[#This Row],[Age]]<30,"20s",EmployeeData[[#This Row],[Age]]<40,"30s",EmployeeData[[#This Row],[Age]]<50,"40s",EmployeeData[[#This Row],[Age]]<60,"50s",EmployeeData[[#This Row],[Age]]>=60,"60s")} -> 20s | G14: 45887 | J14: Active | K14: {=_xlfn.IFS(EmployeeData[[#This Row],[Status]]="Active",_xlfn.DAYS(TODAY(),EmployeeData[[#This Row],[Join Date]]),EmployeeData[[#This Row],[Status]]="Exited",_xlfn.DAYS(EmployeeData[[#This Row],[Exit Date]],EmployeeData[[#This Row],[Join Date]]))} -> 310 | L14: {=_xlfn.IFS(EmployeeData[[#This Row],[Status]]="Exited",DATEDIF(EmployeeData[[#This Row],[Join Date]], EmployeeData[[#This Row],[Exit Date]], "Y"),EmployeeData[[#This Row],[Status]]="Active",DATEDIF(EmployeeData[[#This Row],[Join Date]], TODAY(), "Y"))} -> 0 | Q14: {=_xlfn.IFS(EmployeeData[[#This Row],[Status]]="Exited",DATEDIF(EmployeeData[[#This Row],[Join Date]], EmployeeData[[#This Row],[Exit Date]], "Y") & " years " & DATEDIF(EmployeeData[[#This Row],[Join Date]], EmployeeData[[#This Row],[Exit Date]], "YM") & " months " & DATEDIF(EmployeeData[[#This Row],[Join Date]], EmployeeData[[#This Row],[Exit Date]], "MD") & " days",EmployeeData[[#This Row],[Status]]="Active",DATEDIF(EmployeeData[[#This Row],[Join Date]], TODAY(), "Y") & " years " & DATEDIF(EmployeeData[[#This Row],[Join Date]], TODAY(), "YM") & " months " & DATEDIF(EmployeeData[[#This Row],[Join Date]], TODAY(), "MD") & " days")} -> 0 years 10 months 6 days
A15: 1014 | B15: Jacqueline Bagtas | C15: IT | D15: Female | E15: 31 | F15: {=_xlfn.IFS(EmployeeData[[#This Row],[Age]]<30,"20s",EmployeeData[[#This Row],[Age]]<40,"30s",EmployeeData[[#This Row],[Age]]<50,"40s",EmployeeData[[#This Row],[Age]]<60,"50s",EmployeeData[[#This Row],[Age]]>=60,"60s")} -> 30s | G15: 44959 | H15: 45588 | I15: Contract End | J15: Exited | K15: {=_xlfn.IFS(EmployeeData[[#This Row],[Status]]="Active",_xlfn.DAYS(TODAY(),EmployeeData[[#This Row],[Join Date]]),EmployeeData[[#This Row],[Status]]="Exited",_xlfn.DAYS(EmployeeData[[#This Row],[Exit Date]],EmployeeData[[#This Row],[Join Date]]))} -> 629 | L15: {=_xlfn.IFS(EmployeeData[[#This Row],[Status]]="Exited",DATEDIF(EmployeeData[[#This Row],[Join Date]], EmployeeData[[#This Row],[Exit Date]], "Y"),EmployeeData[[#This Row],[Status]]="Active",DATEDIF(EmployeeData[[#This Row],[Join Date]], TODAY(), "Y"))} -> 1 | Q15: {=_xlfn.IFS(EmployeeData[[#This Row],[Status]]="Exited",DATEDIF(EmployeeData[[#This Row],[Join Date]], EmployeeData[[#This Row],[Exit Date]], "Y") & " years " & DATEDIF(EmployeeData[[#This Row],[Join Date]], EmployeeData[[#This Row],[Exit Date]], "YM") & " months " & DATEDIF(EmployeeData[[#This Row],[Join Date]], EmployeeData[[#This Row],[Exit Date]], "MD") & " days",EmployeeData[[#This Row],[Status]]="Active",DATEDIF(EmployeeData[[#This Row],[Join Date]], TODAY(), "Y") & " years " & DATEDIF(EmployeeData[[#This Row],[Join Date]], TODAY(), "YM") & " months " & DATEDIF(EmployeeData[[#This Row],[Join Date]], TODAY(), "MD") & " days")} -> 1 years 8 months 21 days
A16: 1015 | B16: Paz Elegado | C16: Sales | D16: Female | E16: 53 | F16: {=_xlfn.IFS(EmployeeData[[#This Row],[Age]]<30,"20s",EmployeeData[[#This Row],[Age]]<40,"30s",EmployeeData[[#This Row],[Age]]<50,"40s",EmployeeData[[#This Row],[Age]]<60,"50s",EmployeeData[[#This Row],[Age]]>=60,"60s")} -> 50s | G16: 45595 | H16: 45876 | I16: Personal Reasons | J16: Exited | K16: {=_xlfn.IFS(EmployeeData[[#This Row],[Status]]="Active",_xlfn.DAYS(TODAY(),EmployeeData[[#This Row],[Join Date]]),EmployeeData[[#This Row],[Status]]="Exited",_xlfn.DAYS(EmployeeData[[#This Row],[Exit Date]],EmployeeData[[#This Row],[Join Date]]))} -> 281 | L16: {=_xlfn.IFS(EmployeeData[[#This Row],[Status]]="Exited",DATEDIF(EmployeeData[[#This Row],[Join Date]], EmployeeData[[#This Row],[Exit Date]], "Y"),EmployeeData[[#This Row],[Status]]="Active",DATEDIF(EmployeeData[[#This Row],[Join Date]], TODAY(), "Y"))} -> 0 | Q16: {=_xlfn.IFS(EmployeeData[[#This Row],[Status]]="Exited",DATEDIF(EmployeeData[[#This Row],[Join Date]], EmployeeData[[#This Row],[Exit Date]], "Y") & " years " & DATEDIF(EmployeeData[[#This Row],[Join Date]], EmployeeData[[#This Row],[Exit Date]], "YM") & " months " & DATEDIF(EmployeeData[[#This Row],[Join Date]], EmployeeData[[#This Row],[Exit Date]], "MD") & " days",EmployeeData[[#This Row],[Status]]="Active",DATEDIF(EmployeeData[[#This Row],[Join Date]], TODAY(), "Y") & " years " & DATEDIF(EmployeeData[[#This Row],[Join Date]], TODAY(), "YM") & " months " & DATEDIF(EmployeeData[[#This Row],[Join Date]], TODAY(), "MD") & " days")} -> 0 years 9 months 8 days
A17: 1016 | B17: Christian Garcia Sy | C17: Marketing | D17: Male | E17: 28 | F17: {=_xlfn.IFS(EmployeeData[[#This Row],[Age]]<30,"20s",EmployeeData[[#This Row],[Age]]<40,"30s",EmployeeData[[#This Row],[Age]]<50,"40s",EmployeeData[[#This Row],[Age]]<60,"50s",EmployeeData[[#This Row],[Age]]>=60,"60s")} -> 20s | G17: 44587 | J17: Active | K17: {=_xlfn.IFS(EmployeeData[[#This Row],[Status]]="Active",_xlfn.DAYS(TODAY(),EmployeeData[[#This Row],[Join Date]]),EmployeeData[[#This Row],[Status]]="Exited",_xlfn.DAYS(EmployeeData[[#This Row],[Exit Date]],EmployeeData[[#This Row],[Join Date]]))} -> 1610 | L17: {=_xlfn.IFS(EmployeeData[[#This Row],[Status]]="Exited",DATEDIF(EmployeeData[[#This Row],[Join Date]], EmployeeData[[#This Row],[Exit Date]], "Y"),EmployeeData[[#This Row],[Status]]="Active",DATEDIF(EmployeeData[[#This Row],[Join Date]], TODAY(), "Y"))} -> 4 | Q17: {=_xlfn.IFS(EmployeeData[[#This Row],[Status]]="Exited",DATEDIF(EmployeeData[[#This Row],[Join Date]], EmployeeData[[#This Row],[Exit Date]], "Y") & " years " & DATEDIF(EmployeeData[[#This Row],[Join Date]], EmployeeData[[#This Row],[Exit Date]], "YM") & " months " & DATEDIF(EmployeeData[[#This Row],[Join Date]], EmployeeData[[#This Row],[Exit Date]], "MD") & " days",EmployeeData[[#This Row],[Status]]="Active",DATEDIF(EmployeeData[[#This Row],[Join Date]], TODAY(), "Y") & " years " & DATEDIF(EmployeeData[[#This Row],[Join Date]], TODAY(), "YM") & " months " & DATEDIF(EmployeeData[[#This Row],[Join Date]], TODAY(), "MD") & " days")} -> 4 years 4 months 29 days
A18: 1017 | B18: Bernardo Lopez Delos Reyes | C18: Customer Support | D18: Male | E18: 25 | F18: {=_xlfn.IFS(EmployeeData[[#This Row],[Age]]<30,"20s",EmployeeData[[#This Row],[Age]]<40,"30s",EmployeeData[[#This Row],[Age]]<50,"40s",EmployeeData[[#This Row],[Age]]<60,"50s",EmployeeData[[#This Row],[Age]]>=60,"60s")} -> 20s | G18: 45282 | J18: Active | K18: {=_xlfn.IFS(EmployeeData[[#This Row],[Status]]="Active",_xlfn.DAYS(TODAY(),EmployeeData[[#This Row],[Join Date]]),EmployeeData[[#This Row],[Status]]="Exited",_xlfn.DAYS(EmployeeData[[#This Row],[Exit Date]],EmployeeData[[#This Row],[Join Date]]))} -> 915 | L18: {=_xlfn.IFS(EmployeeData[[#This Row],[Status]]="Exited",DATEDIF(EmployeeData[[#This Row],[Join Date]], EmployeeData[[#This Row],[Exit Date]], "Y"),EmployeeData[[#This Row],[Status]]="Active",DATEDIF(EmployeeData[[#This Row],[Join Date]], TODAY(), "Y"))} -> 2 | Q18: {=_xlfn.IFS(EmployeeData[[#This Row],[Status]]="Exited",DATEDIF(EmployeeData[[#This Row],[Join Date]], EmployeeData[[#This Row],[Exit Date]], "Y") & " years " & DATEDIF(EmployeeData[[#This Row],[Join Date]], EmployeeData[[#This Row],[Exit Date]], "YM") & " months " & DATEDIF(EmployeeData[[#This Row],[Join Date]], EmployeeData[[#This Row],[Exit Date]], "MD") & " days",EmployeeData[[#This Row],[Status]]="Active",DATEDIF(EmployeeData[[#This Row],[Join Date]], TODAY(), "Y") & " years " & DATEDIF(EmployeeData[[#This Row],[Join Date]], TODAY(), "YM") & " months " & DATEDIF(EmployeeData[[#This Row],[Join Date]], TODAY(), "MD") & " days")} -> 2 years 6 months 2 days
A19: 1018 | B19: Miguel Santiago Miranda | C19: IT | D19: Other | E19: 48 | F19: {=_xlfn.IFS(EmployeeData[[#This Row],[Age]]<30,"20s",EmployeeData[[#This Row],[Age]]<40,"30s",EmployeeData[[#This Row],[Age]]<50,"40s",EmployeeData[[#This Row],[Age]]<60,"50s",EmployeeData[[#This Row],[Age]]>=60,"60s")} -> 40s | G19: 43968 | J19: Active | K19: {=_xlfn.IFS(EmployeeData[[#This Row],[Status]]="Active",_xlfn.DAYS(TODAY(),EmployeeData[[#This Row],[Join Date]]),EmployeeData[[#This Row],[Status]]="Exited",_xlfn.DAYS(EmployeeData[[#This Row],[Exit Date]],EmployeeData[[#This Row],[Join Date]]))} -> 2229 | L19: {=_xlfn.IFS(EmployeeData[[#This Row],[Status]]="Exited",DATEDIF(EmployeeData[[#This Row],[Join Date]], EmployeeData[[#This Row],[Exit Date]], "Y"),EmployeeData[[#This Row],[Status]]="Active",DATEDIF(EmployeeData[[#This Row],[Join Date]], TODAY(), "Y"))} -> 6 | Q19: {=_xlfn.IFS(EmployeeData[[#This Row],[Status]]="Exited",DATEDIF(EmployeeData[[#This Row],[Join Date]], EmployeeData[[#This Row],[Exit Date]], "Y") & " years " & DATEDIF(EmployeeData[[#This Row],[Join Date]], EmployeeData[[#This Row],[Exit Date]], "YM") & " months " & DATEDIF(EmployeeData[[#This Row],[Join Date]], EmployeeData[[#This Row],[Exit Date]], "MD") & " days",EmployeeData[[#This Row],[Status]]="Active",DATEDIF(EmployeeData[[#This Row],[Join Date]], TODAY(), "Y") & " years " & DATEDIF(EmployeeData[[#This Row],[Join Date]], TODAY(), "YM") & " months " & DATEDIF(EmployeeData[[#This Row],[Join Date]], TODAY(), "MD") & " days")} -> 6 years 1 months 7 days
A20: 1019 | B20: Pete Santos Lim | C20: IT | D20: Male | E20: 28 | F20: {=_xlfn.IFS(EmployeeData[[#This Row],[Age]]<30,"20s",EmployeeData[[#This Row],[Age]]<40,"30s",EmployeeData[[#This Row],[Age]]<50,"40s",EmployeeData[[#This Row],[Age]]<60,"50s",EmployeeData[[#This Row],[Age]]>=60,"60s")} -> 20s | G20: 44116 | H20: 44898 | I20: Better Opportunity | J20: Exited | K20: {=_xlfn.IFS(EmployeeData[[#This Row],[Status]]="Active",_xlfn.DAYS(TODAY(),EmployeeData[[#This Row],[Join Date]]),EmployeeData[[#This Row],[Status]]="Exited",_xlfn.DAYS(EmployeeData[[#This Row],[Exit Date]],EmployeeData[[#This Row],[Join Date]]))} -> 782 | L20: {=_xlfn.IFS(EmployeeData[[#This Row],[Status]]="Exited",DATEDIF(EmployeeData[[#This Row],[Join Date]], EmployeeData[[#This Row],[Exit Date]], "Y"),EmployeeData[[#This Row],[Status]]="Active",DATEDIF(EmployeeData[[#This Row],[Join Date]], TODAY(), "Y"))} -> 2 | Q20: {=_xlfn.IFS(EmployeeData[[#This Row],[Status]]="Exited",DATEDIF(EmployeeData[[#This Row],[Join Date]], EmployeeData[[#This Row],[Exit Date]], "Y") & " years " & DATEDIF(EmployeeData[[#This Row],[Join Date]], EmployeeData[[#This Row],[Exit Date]], "YM") & " months " & DATEDIF(EmployeeData[[#This Row],[Join Date]], EmployeeData[[#This Row],[Exit Date]], "MD") & " days",EmployeeData[[#This Row],[Status]]="Active",DATEDIF(EmployeeData[[#This Row],[Join Date]], TODAY(), "Y") & " years " & DATEDIF(EmployeeData[[#This Row],[Join Date]], TODAY(), "YM") & " months " & DATEDIF(EmployeeData[[#This Row],[Join Date]], TODAY(), "MD") & " days")} -> 2 years 1 months 21 days
